Workbook
Name Responsable: Source!$A$1:$A$3

Sheet Planification
B1: Planification globale
A5: No. | B5: Tâche | C5: Sprint visé | D5: Priorité | E5: Durée prévue (heures) | F5: Tâches Préalables
A6: 1 | B6: Document de définition | C6: Sprint 1 | D6: Haute | E6: 3
A7: 2 | B7: Document de planification | C7: Sprint 1 | D7: Haute | E7: 2
A8: 3 | B8: Diagramme de cas d'usage | C8: Sprint 1 | D8: Haute | E8: 3
A9: 4 | B9: Diagramme de classe | C9: Sprint 1 | D9: Haute | E9: 3
A10: 5 | B10: Diagramme des bases de données | C10: Sprint 1 | D10: Haute | E10: 3
A11: 6 | B11: Maquettes du UI | C11: Sprint 1 | D11: Moyenne | E11: 2.5
A12: 7 | B12: Document de conception | C12: Sprint 1 | D12: Moyenne | E12: 2 | F12: 3, 4, 5, 6
A13: 9 | B13: Créer un nouveau projet Expo | C13: Sprint 2 | D13: Haute | E13: 4
A14: 10 | B14: Créer un Game Manager | C14: Sprint 2 | D14: Haute | E14: 6
A15: 12 | B15: Créer le modèle de jeu (pas de EffectSequence) | C15: Sprint 2 | D15: Haute | E15: 7 | F15: 10
A16: 21 | B16: Command : RollCommand | C16: Sprint 2 | D16: Haute | E16: 2 | F16: 19, 12
A17: 23 | B17: Command : UseDiceCommand | C17: Sprint 2 | D17: Haute | E17: 2 | F17: 19, 12
A18: 40 | B18: Création de l'interface de Command et sérialisation (Client -> Node.js) | C18: Sprint 2 | D18: Haute | E18: 5 | F18: 10
A19: 39 | B19: Intégration du web socket dans Expo | C19: Sprint 2 | D19: Haute | E19: 4
A20: 8 | B20: Creation d'un usager | C20: Sprint 2 | D20: Moyenne | E20: 3 | F20: 9, 10
A21: 11 | B21: Lancer une partie Entraînement (Joueur C. IA) | C21: Sprint 2 | D21: Moyenne | E21: 5 | F21: 12
A22: 15 | B22: Créer la page religion | C22: Sprint 2 | D22: Moyenne | E22: 4 | F22: 9
A23: 16 | B23: Créer la page artefact | C23: Sprint 2 | D23: Moyenne | E23: 4 | F23: 9
A24: 17 | B24: Créer la page combat (bouton pour lancer une partie) | C24: Sprint 2 | D24: Moyenne | E24: 2 | F24: 9
A25: 19 | B25: Créer une page de partie (version basique) | C25: Sprint 2 | D25: Moyenne | E25: 8 | F25: 9
A26: 22 | B26: Command : LockCommand | C26: Sprint 2 | D26: Moyenne | E26: 2 | F26: 19, 12, 21
A27: 13 | B27: Modifier sa religion (UpdateReligionCommand) | C27: Sprint 2 | D27: Basse | E27: 2 | F27: 15
A28: 14 | B28: Modifier ses artefacts (UpdateArtifactCommand) | C28: Sprint 2 | D28: Basse | E28: 2 | F28: 16
A29: 18 | B29: Ajouter un chrono (temps de jeu) | C29: Sprint 2 | D29: Basse | E29: 2 | F29: 19
A30: 20 | B30: Command : EnchantCommand | C30: Sprint 2 | D30: Basse | E30: 2 | F30: 19, 12, 21
A31: 24 | B31: Command: ForfeitCommand | C31: Sprint 2 | D31: Basse | E31: 2 | F31: 19.12
A32: 25 | B32: Command : EndPhaseCommand | C32: Sprint 2 | D32: Basse | E32: 2 | F32: 19.12
A33: 26 | B33: Ajout de la Prayer Phase (passive effect) | C33: Sprint 2 | D33: Basse | E33: 2 | F33: 12
A34: 27 | B34: Créer une machine virtuelle Digital Ocean | C34: Sprint 3 | D34: Haute | E34: 3.5
A35: 28 | B35: Créer une base de données SQL | C35: Sprint 3 | D35: Haute | E35: 6 | F35: 27
A36: 29 | B36: Créer le DAO dans Game Manager | C36: Sprint 3 | D36: Haute | E36: 4 | F36: 28
A37: 30 | B37: Héberger serveur sur la machine virtuelle | C37: Sprint 3 | D37: Haute | E37: 8 | F37: 27
A38: 33 | B38: Command : FindMatchCommand (Joueur C. Joueur) | C38: Sprint 3 | D38: Haute | E38: 2 | F38: 41
A39: 31 | B39: Command : ArtifactCommand | C39: Sprint 3 | D39: Moyenne | E39: 5 | F39: 35
A40: 32 | B40: Command : SummonCommand | C40: Sprint 3 | D40: Moyenne | E40: 3 | F40: 35
A41: 34 | B41: Creation des effect Sequence | C41: Sprint 3 | D41: Moyenne | E41: 6 | F41: 38
A42: 35 | B42: Creation du EffectSequence Factory | C42: Sprint 3 | D42: Moyenne | E42: 4 | F42: 34
A43: 37 | B43: Formatage du visuel des artefacts | C43: Sprint 3 | D43: Moyenne | E43: 6 | F43: 28
...

Sheet Sprint 1
B1: Sprint 1
D3: Semaine A | G3: Semaine B | J3: Semaine C
B4: Tâche | C4: Responsable | D4: Temps (hrs) | E4: Avancement (%) | F4: Commentaires | G4: Temps | H4: Avancement | I4: Commentaires | J4: Temps | K4: Avancement | L4: Commentaires
B5: {=IFERROR( INDEX(Planification!B$2:B$100, SMALL( IF(Planification!C$2:C$100="Sprint 1", ROW(Planification!B$2:B$100)-ROW(Planification!B$2)+1), ROW(A1) ) ), "")} -> Document de définition | C5: Fred & Hugo | D5: 1 | E5: 50 | F5: Reste à finir les exigences | G5: 1.5 | H5: 90 | I5: Reste à réviser et faire un PDF | J5: 0.5 | K5: 100 | L5: Terminé
B6: {=IFERROR( INDEX(Planification!B$2:B$100, SMALL( IF(Planification!C$2:C$100="Sprint 1", ROW(Planification!B$2:B$100)-ROW(Planification!B$2)+1), ROW(A2) ) ), "")} -> Document de planification | C6: Fred & Hugo | J6: 2 | K6: 100 | L6: Terminé
B7: {=IFERROR( INDEX(Planification!B$2:B$100, SMALL( IF(Planification!C$2:C$100="Sprint 1", ROW(Planification!B$2:B$100)-ROW(Planification!B$2)+1), ROW(A3) ) ), "")} -> Diagramme de cas d'usage | C7: Fred & Hugo | D7: 3 | E7: 100 | F7: Terminé
B8: {=IFERROR( INDEX(Planification!B$2:B$100, SMALL( IF(Planification!C$2:C$100="Sprint 1", ROW(Planification!B$2:B$100)-ROW(Planification!B$2)+1), ROW(A4) ) ), "")} -> Diagramme de classe | C8: Fred & Hugo | D8: 2 | E8: 30 | F8: Il faut réfléchir aux patrons de conceptions | G8: 4 | H8: 90 | I8: Intégration de command et factory | J8: 0.5 | K8: 100 | L8: Terminé
B9: {=IFERROR( INDEX(Planification!B$2:B$100, SMALL( IF(Planification!C$2:C$100="Sprint 1", ROW(Planification!B$2:B$100)-ROW(Planification!B$2)+1), ROW(A5) ) ), "")} -> Diagramme des bases de données | C9: Fred & Hugo | G9: 1.5 | H9: 100 | I9: Terminé
B10: {=IFERROR( INDEX(Planification!B$2:B$100, SMALL( IF(Planification!C$2:C$100="Sprint 1", ROW(Planification!B$2:B$100)-ROW(Planification!B$2)+1), ROW(A6) ) ), "")} -> Maquettes du UI | C10: Fred & Hugo | J10: 3.5 | K10: 100 | L10: Terminé
B11: {=IFERROR( INDEX(Planification!B$2:B$100, SMALL( IF(Planification!C$2:C$100="Sprint 1", ROW(Planification!B$2:B$100)-ROW(Planification!B$2)+1), ROW(A7) ) ), "")} -> Document de conception | C11: Fred & Hugo | J11: 1 | K11: 100 | L11: Terminé
B12: {=IFERROR( INDEX(Planification!B$2:B$100, SMALL( IF(Planification!C$2:C$100="Sprint 1", ROW(Planification!B$2:B$100)-ROW(Planification!B$2)+1), ROW(A8) ) ), "")}
B13: {=IFERROR( INDEX(Planification!B$2:B$100, SMALL( IF(Planification!C$2:C$100="Sprint 1", ROW(Planification!B$2:B$100)-ROW(Planification!B$2)+1), ROW(A9) ) ), "")}
B14: {=IFERROR( INDEX(Planification!B$2:B$100, SMALL( IF(Planification!C$2:C$100="Sprint 1", ROW(Planification!B$2:B$100)-ROW(Planification!B$2)+1), ROW(A10) ) ), "")}
B15: {=IFERROR( INDEX(Planification!B$2:B$100, SMALL( IF(Planification!C$2:C$100="Sprint 1", ROW(Planification!B$2:B$100)-ROW(Planification!B$2)+1), ROW(A11) ) ), "")}
B16: {=IFERROR( INDEX(Planification!B$2:B$100, SMALL( IF(Planification!C$2:C$100="Sprint 1", ROW(Planification!B$2:B$100)-ROW(Planification!B$2)+1), ROW(A12) ) ), "")}
B17: {=IFERROR( INDEX(Planification!B$2:B$100, SMALL( IF(Planification!C$2:C$100="Sprint 1", ROW(Planification!B$2:B$100)-ROW(Planification!B$2)+1), ROW(A13) ) ), "")}
B18: {=IFERROR( INDEX(Planification!B$2:B$100, SMALL( IF(Planification!C$2:C$100="Sprint 1", ROW(Planification!B$2:B$100)-ROW(Planification!B$2)+1), ROW(A14) ) ), "")}
B19: {=IFERROR( INDEX(Planification!B$2:B$100, SMALL( IF(Planification!C$2:C$100="Sprint 1", ROW(Planification!B$2:B$100)-ROW(Planification!B$2)+1), ROW(A15) ) ), "")}
B20: {=IFERROR( INDEX(Planification!B$2:B$100, SMALL( IF(Planification!C$2:C$100="Sprint 1", ROW(Planification!B$2:B$100)-ROW(Planification!B$2)+1), ROW(A16) ) ), "")}
B21: {=IFERROR( INDEX(Planification!B$2:B$100, SMALL( IF(Planification!C$2:C$100="Sprint 1", ROW(Planification!B$2:B$100)-ROW(Planification!B$2)+1), ROW(A17) ) ), "")}
B22: {=IFERROR( INDEX(Planification!B$2:B$100, SMALL( IF(Planification!C$2:C$100="Sprint 1", ROW(Planification!B$2:B$100)-ROW(Planification!B$2)+1), ROW(A18) ) ), "")}
B23: {=IFERROR( INDEX(Planification!B$2:B$100, SMALL( IF(Planification!C$2:C$100="Sprint 1", ROW(Planification!B$2:B$100)-ROW(Planification!B$2)+1), ROW(A19) ) ), "")}
... B41: {=IFERROR( INDEX(Planification!B$2:B$100, SMALL( IF(Planification!C$2:C$100="Sprint 1", ROW(Planification!B$2:B$100)-ROW(Planification!B$2)+1), ROW(A37) ) ), "")}

Sheet Source
A1: Fred
A2: Hugo
A3: Fred & Hugo

Sheet Sprint 2
B1: Sprint 2
D3: Semaine A | G3: Semaine B | J3: Semaine C
B4: Tâche | C4: Responsable | D4: Temps (hrs) | E4: Avancement (%) | F4: Commentaires | G4: Temps | H4: Avancement | I4: Commentaires | J4: Temps | K4: Avancement | L4: Commentaires
B5: {=IFERROR( INDEX(Planification!B$2:B$100, SMALL( IF(Planification!C$2:C$100="Sprint 2", ROW(Planification!B$2:B$100)-ROW(Planification!B$2)+1), ROW(A1) ) ), "")} -> Créer un nouveau projet Expo | C5: Fred | D5: 6.5 | E5: 1 | F5: Expo Globale avec Navbar à custom dans Sprint 4
B6: {=IFERROR( INDEX(Planification!B$2:B$100, SMALL( IF(Planification!C$2:C$100="Sprint 2", ROW(Planification!B$2:B$100)-ROW(Planification!B$2)+1), ROW(A2) ) ), "")} -> Créer un Game Manager | C6: Hugo | D6: 2.5 | E6: 0.1 | F6: prototype, appel au serveur | G6: 2.5 | H6: 0.6 | I6: reception et renvoie des messages (on devrais avior des gameState au lieu de renvoyer seulement l'information qui a été modifié) | J6: 2.5 | K6: 0.7 | L6: appel générique des commandes et Singleton, il manque une connexion au DAO, mais ca cest pour les prochains sprints
B7: {=IFERROR( INDEX(Planification!B$2:B$100, SMALL( IF(Planification!C$2:C$100="Sprint 2", ROW(Planification!B$2:B$100)-ROW(Planification!B$2)+1), ROW(A3) ) ), "")} -> Créer le modèle de jeu (pas de EffectSequence) | C7: Hugo | D7: 2.5 | E7: 0.1 | F7: Éviter de construire de bas en haut, commencer avec partie et GameManager | G7: 2.5 | H7: 0.7 | J7: 2.5 | K7: 0.9 | L7: changement de fonctionnements des actions…
B8: {=IFERROR( INDEX(Planification!B$2:B$100, SMALL( IF(Planification!C$2:C$100="Sprint 2", ROW(Planification!B$2:B$100)-ROW(Planification!B$2)+1), ROW(A4) ) ), "")} -> Command : RollCommand | C8: Fred & Hugo | G8: 4 | H8: 1 | I8: Mise en place de Command Factory
B9: {=IFERROR( INDEX(Planification!B$2:B$100, SMALL( IF(Planification!C$2:C$100="Sprint 2", ROW(Planification!B$2:B$100)-ROW(Planification!B$2)+1), ROW(A5) ) ), "")} -> Command : UseDiceCommand | C9: Fred | J9: 3 | K9: 1 | L9: Fonctionnel (Gesture à améliorer au sprint 4
B10: {=IFERROR( INDEX(Planification!B$2:B$100, SMALL( IF(Planification!C$2:C$100="Sprint 2", ROW(Planification!B$2:B$100)-ROW(Planification!B$2)+1), ROW(A6) ) ), "")} -> Création de l'interface de Command et sérialisation (Client -> Node.js) | C10: Fred & Hugo
B11: {=IFERROR( INDEX(Planification!B$2:B$100, SMALL( IF(Planification!C$2:C$100="Sprint 2", ROW(Planification!B$2:B$100)-ROW(Planification!B$2)+1), ROW(A7) ) ), "")} -> Intégration du web socket dans Expo | C11: Fred | D11: 4 | E11: 1 | F11: À mettre à jour une fois Digital Ocean fonctionnel, il s'agit d'un service avec un ContextProvider
B12: {=IFERROR( INDEX(Planification!B$2:B$100, SMALL( IF(Planification!C$2:C$100="Sprint 2", ROW(Planification!B$2:B$100)-ROW(Planification!B$2)+1), ROW(A8) ) ), "")} -> Creation d'un usager
B13: {=IFERROR( INDEX(Planification!B$2:B$100, SMALL( IF(Planification!C$2:C$100="Sprint 2", ROW(Planification!B$2:B$100)-ROW(Planification!B$2)+1), ROW(A9) ) ), "")} -> Lancer une partie Entraînement (Joueur C. IA) | C13: Fred & Hugo | G13: 6 | H13: 0.5 | I13: Mise en place des phases de jeu et des interactions possible dans le client | J13: 3 | K13: 0.7 | L13: Reste à clarifier le timing des phases
B14: {=IFERROR( INDEX(Planification!B$2:B$100, SMALL( IF(Planification!C$2:C$100="Sprint 2", ROW(Planification!B$2:B$100)-ROW(Planification!B$2)+1), ROW(A10) ) ), "")} -> Créer la page religion | C14: Fred | K14: 0 | L14: À faire dans Sprint 3 une fois que gods et EffectSequence seront prêts
B15: {=IFERROR( INDEX(Planification!B$2:B$100, SMALL( IF(Planification!C$2:C$100="Sprint 2", ROW(Planification!B$2:B$100)-ROW(Planification!B$2)+1), ROW(A11) ) ), "")} -> Créer la page artefact | C15: Fred | G15: 3 | H15: 0.3 | I15: Test avec Skia + intégration d'une flatList d'artefacts
B16: {=IFERROR( INDEX(Planification!B$2:B$100, SMALL( IF(Planification!C$2:C$100="Sprint 2", ROW(Planification!B$2:B$100)-ROW(Planification!B$2)+1), ROW(A12) ) ), "")} -> Créer la page combat (bouton pour lancer une partie) | C16: Fred | G16: 1
B17: {=IFERROR( INDEX(Planification!B$2:B$100, SMALL( IF(Planification!C$2:C$100="Sprint 2", ROW(Planification!B$2:B$100)-ROW(Planification!B$2)+1), ROW(A13) ) ), "")} -> Créer une page de partie (version basique) | C17: Fred | G17: 3 | H17: 0.3 | I17: Affichage des dés et possibiliter d'envoyer roll et lock command | J17: 3 | K17: 0.6 | L17: Reste à intégrer les visuels des statistiques du joueur
B18: {=IFERROR( INDEX(Planification!B$2:B$100, SMALL( IF(Planification!C$2:C$100="Sprint 2", ROW(Planification!B$2:B$100)-ROW(Planification!B$2)+1), ROW(A14) ) ), "")} -> Command : LockCommand | C18: Fred & Hugo | G18: 2 | H18: 1
B19: {=IFERROR( INDEX(Planification!B$2:B$100, SMALL( IF(Planification!C$2:C$100="Sprint 2", ROW(Planification!B$2:B$100)-ROW(Planification!B$2)+1), ROW(A15) ) ), "")} -> Modifier sa religion (UpdateReligionCommand)
B20: {=IFERROR( INDEX(Planification!B$2:B$100, SMALL( IF(Planification!C$2:C$100="Sprint 2", ROW(Planification!B$2:B$100)-ROW(Planification!B$2)+1), ROW(A16) ) ), "")} -> Modifier ses artefacts (UpdateArtifactCommand)
B21: {=IFERROR( INDEX(Planification!B$2:B$100, SMALL( IF(Planification!C$2:C$100="Sprint 2", ROW(Planification!B$2:B$100)-ROW(Planification!B$2)+1), ROW(A17) ) ), "")} -> Ajouter un chrono (temps de jeu) | C21: Fred & Hugo | G21: 2 | H21: 0.7 | I21: Faut brancher les phases de jeu avec la fin du Timer
B22: {=IFERROR( INDEX(Planification!B$2:B$100, SMALL( IF(Planification!C$2:C$100="Sprint 2", ROW(Planification!B$2:B$100)-ROW(Planification!B$2)+1), ROW(A18) ) ), "")} -> Command : EnchantCommand
B23: {=IFERROR( INDEX(Planification!B$2:B$100, SMALL( IF(Planification!C$2:C$100="Sprint 2", ROW(Planification!B$2:B$100)-ROW(Planification!B$2)+1), ROW(A19) ) ), "")} -> Command: ForfeitCommand | C23: Hugo | G23: 2.5 | H23: 1 | K23: 0.9 | L23: on doit bien gérer la déconnexion de la partie, le retour en mémoire de cette derniere et la deconnexion des sockets
B24: {=IFERROR( INDEX(Planification!B$2:B$100, SMALL( IF(Planification!C$2:C$100="Sprint 2", ROW(Planification!B$2:B$100)-ROW(Planification!B$2)+1), ROW(A20) ) ), "")} -> Command : EndPhaseCommand | C24: Hugo | G24: 2.5 | H24: 0.5
B25: CommandFactory | C25: Hugo | J25: 1.5 | K25: 1 | L25: on doir ajouter a la map des commandes legales a chauqes nouvelle commande, mais 100% fonctionnel et generique
B26: {=IFERROR( INDEX(Planification!B$2:B$100, SMALL( IF(Planification!C$2:C$100="Sprint 2", ROW(Planification!B$2:B$100)-ROW(Planification!B$2)+1), ROW(A22) ) ), "")}
B27: {=IFERROR( INDEX(Planification!B$2:B$100, SMALL( IF(Planification!C$2:C$100="Sprint 2", ROW(Planification!B$2:B$100)-ROW(Planification!B$2)+1), ROW(A23) ) ), "")}
B28: {=IFERROR( INDEX(Planification!B$2:B$100, SMALL( IF(Planification!C$2:C$100="Sprint 2", ROW(Planification!B$2:B$100)-ROW(Planification!B$2)+1), ROW(A24) ) ), "")}
B29: {=IFERROR( INDEX(Planification!B$2:B$100, SMALL( IF(Planification!C$2:C$100="Sprint 2", ROW(Planification!B$2:B$100)-ROW(Planification!B$2)+1), ROW(A25) ) ), "")}
B30: {=IFERROR( INDEX(Planification!B$2:B$100, SMALL( IF(Planification!C$2:C$100="Sprint 2", ROW(Planification!B$2:B$100)-ROW(Planification!B$2)+1), ROW(A26) ) ), "")}
B31: {=IFERROR( INDEX(Planification!B$2:B$100, SMALL( IF(Planification!C$2:C$100="Sprint 2", ROW(Planification!B$2:B$100)-ROW(Planification!B$2)+1), ROW(A27) ) ), "")}
B32: {=IFERROR( INDEX(Planification!B$2:B$100, SMALL( IF(Planification!C$2:C$100="Sprint 2", ROW(Planification!B$2:B$100)-ROW(Planification!B$2)+1), ROW(A28) ) ), "")}
B33: {=IFERROR( INDEX(Planification!B$2:B$100, SMALL( IF(Planification!C$2:C$100="Sprint 2", ROW(Planification!B$2:B$100)-ROW(Planification!B$2)+1), ROW(A29) ) ), "")}
B34: {=IFERROR( INDEX(Planification!B$2:B$100, SMALL( IF(Planification!C$2:C$100="Sprint 2", ROW(Planification!B$2:B$100)-ROW(Planification!B$2)+1), ROW(A30) ) ), "")}
B35: {=IFERROR( INDEX(Planification!B$2:B$100, SMALL( IF(Planification!C$2:C$100="Sprint 2", ROW(Planification!B$2:B$100)-ROW(Planification!B$2)+1), ROW(A31) ) ), "")}
B36: {=IFERROR( INDEX(Planification!B$2:B$100, SMALL( IF(Planification!C$2:C$100="Sprint 2", ROW(Planification!B$2:B$100)-ROW(Planification!B$2)+1), ROW(A32) ) ), "")}
B37: {=IFERROR( INDEX(Planification!B$2:B$100, SMALL( IF(Planification!C$2:C$100="Sprint 2", ROW(Planification!B$2:B$100)-ROW(Planification!B$2)+1), ROW(A33) ) ), "")}
... B41: {=IFERROR( INDEX(Planification!B$2:B$100, SMALL( IF(Planification!C$2:C$100="Sprint 2", ROW(Planification!B$2:B$100)-ROW(Planification!B$2)+1), ROW(A37) ) ), "")}

Sheet Mi-mandat
B1: Mi-mandat
B3: Ce qui est problématique… | C3: Ce qui doit être fait… | D3: Responsible | E3: Temps
B4: on ne peut pas lancer l'app sur un telephone autre | C4: Ajouter le client dans expoCloud *Très Souhaitable*
B5: visuel Lobby | C5: Ajouter une présentation agréable au lobby
B6: visuel religion | C6: ajouter les religions a chiosir
B7: visuel artefact | C7: ajouter les artefacts du joueur en haut
B8: visuel partie | C8: ajouter un visuel agréable a la partie
B9: Ajouter Artrefact
B10: Ajouter Gods
B11: Ajouter Status Effects
B12: formater les effectSequence
B13: Connecter le DAO
B14: matchmaking
B15: gestures lancent des commandes
B16: enum des socketEvents de commande
B23: CHOCOLAT
B24: implementer une logique de jeu pour entrainement | C24: l'IA doit pouvoir utiliser un Artefact et un Dieu
B25: Statistiques
B26: Ajouter un Tutoriel pour une premiere connexion et un combat mock

Sheet Sprint 3
B1: Sprint 3
D3: Semaine A | G3: Semaine B | J3: Semaine C
B4: Tâche | C4: Responsable | D4: Temps (hrs) | E4: Avancement (%) | F4: Commentaires | G4: Temps | H4: Avancement | I4: Commentaires | J4: Temps | K4: Avancement | L4: Commentaires
B5: {=IFERROR( INDEX(Planification!B$2:B$100, SMALL( IF(Planification!C$2:C$100="Sprint 3", ROW(Planification!B$2:B$100)-ROW(Planification!B$2)+1), ROW(A1) ) ), "")} -> Créer une machine virtuelle Digital Ocean | C5: Fred | D5: 5 | E5: 1
B6: {=IFERROR( INDEX(Planification!B$2:B$100, SMALL( IF(Planification!C$2:C$100="Sprint 3", ROW(Planification!B$2:B$100)-ROW(Planification!B$2)+1), ROW(A2) ) ), "")} -> Créer une base de données SQL | C6: Fred | G6: 5 | H6: 0.8 | I6: Reste à implémenter sur Server | J6: 2 | K6: 1 | L6: Installé sur le serveur Ubuntu
B7: {=IFERROR( INDEX(Planification!B$2:B$100, SMALL( IF(Planification!C$2:C$100="Sprint 3", ROW(Planification!B$2:B$100)-ROW(Planification!B$2)+1), ROW(A3) ) ), "")} -> Créer le DAO dans Game Manager | C7: Fred & Hugo | J7: 3 | K7: 0.5 | L7: Connection fonctionne, mais il faut un DAO pour les users et les games
B8: {=IFERROR( INDEX(Planification!B$2:B$100, SMALL( IF(Planification!C$2:C$100="Sprint 3", ROW(Planification!B$2:B$100)-ROW(Planification!B$2)+1), ROW(A4) ) ), "")} -> Héberger serveur sur la machine virtuelle | C8: Fred | D8: 4 | E8: 0.8 | F8: Il reste à debug le webhook pour automatiser le pull serveur lors d'un push sur main
B9: {=IFERROR( INDEX(Planification!B$2:B$100, SMALL( IF(Planification!C$2:C$100="Sprint 3", ROW(Planification!B$2:B$100)-ROW(Planification!B$2)+1), ROW(A5) ) ), "")} -> Command : FindMatchCommand (Joueur C. Joueur)
B10: {=IFERROR( INDEX(Planification!B$2:B$100, SMALL( IF(Planification!C$2:C$100="Sprint 3", ROW(Planification!B$2:B$100)-ROW(Planification!B$2)+1), ROW(A6) ) ), "")} -> Command : ArtifactCommand | C10: Hugo | J10: 2 | K10: 1 | L10: Commande ajoutée et peux etre créée avec la factory
B11: {=IFERROR( INDEX(Planification!B$2:B$100, SMALL( IF(Planification!C$2:C$100="Sprint 3", ROW(Planification!B$2:B$100)-ROW(Planification!B$2)+1), ROW(A7) ) ), "")} -> Command : SummonCommand
B12: {=IFERROR( INDEX(Planification!B$2:B$100, SMALL( IF(Planification!C$2:C$100="Sprint 3", ROW(Planification!B$2:B$100)-ROW(Planification!B$2)+1), ROW(A8) ) ), "")} -> Creation des effect Sequence | C12: Fred | G12: 4 | H12: 1
B13: {=IFERROR( INDEX(Planification!B$2:B$100, SMALL( IF(Planification!C$2:C$100="Sprint 3", ROW(Planification!B$2:B$100)-ROW(Planification!B$2)+1), ROW(A9) ) ), "")} -> Creation du EffectSequence Factory | C13: Fred | G13: 2 | H13: 1 | I13: Création de EffectFactory pour mieux gérer les datas venant de src/server/gameData/*.ts
B14: {=IFERROR( INDEX(Planification!B$2:B$100, SMALL( IF(Planification!C$2:C$100="Sprint 3", ROW(Planification!B$2:B$100)-ROW(Planification!B$2)+1), ROW(A10) ) ), "")} -> Formatage du visuel des artefacts | C14: Fred | D14: 3 | E14: 0.5 | F14: Il reste les effectSequence, cooldown et dice Combo à ajouter
B15: {=IFERROR( INDEX(Planification!B$2:B$100, SMALL( IF(Planification!C$2:C$100="Sprint 3", ROW(Planification!B$2:B$100)-ROW(Planification!B$2)+1), ROW(A11) ) ), "")} -> Creation des Status Effect et de la Status Phase | C15: Fred | G15: 2 | H15: 0.75 | I15: la classe StatusEffect a été ajouté à Player, il reste à changer la status Phase pour activer les status ( à faire après Artifact et SummonCommand)
B16: {=IFERROR( INDEX(Planification!B$2:B$100, SMALL( IF(Planification!C$2:C$100="Sprint 3", ROW(Planification!B$2:B$100)-ROW(Planification!B$2)+1), ROW(A12) ) ), "")} -> Implémentation de la Queue | C16: Hugo | J16: 3 | K16: 0.5 | L16: Classe complété, il reste à implémenter avec le GameManager et Command, reste aussi a tirer deux joueurs de meme rang selon le temps d'attente
B17: Implémentation des statusEffect | C17: Fred & Hugo | J17: 3 | K17: 0.9 | L17: Il reste à bien tester en jeu pour que cela fonctionne, mais touts les status sont implémentés et UnitTestés. Le Status Feu est en état temporaire et sera modifié selon le temps
B18: Formatage du visuel des GodWidget | C18: Fred | G18: 4 | H18: 0.75 | I18: Il reste à faire un peu de ménage dans le composant et ajouté le EffectSequence
B19: Faire des spritesheets( gods, artifacts, icons) | C19: Fred | J19: 2 | K19: 1 | L19: Implémentation des designs de Canva Complété
B20: Faire un composant générique spritesheet | C20: Fred | J20: 2 | K20: 1 | L20: Permet d'avoir un composant générique qui applique une translation horizontale selon le frame index
B21: Implémentation de la classe Gods | C21: Hugo | J21: 2 | K21: 0.5 | L21: Il reste à faire des tests et GodCommand
B22: Implémentation de la classe Artifact | C22: Hugo | G22: 2 | H22: 0.5 | J22: 4 | K22: 1 | L22: Classe Complétée et testée avec JUnit
B23: SwapArtifact Command | C23: Fred | J23: 1 | K23: 1 | L23: Fonctionnel
B24: Peaufinage du menu Artifact | C24: Fred | J24: 4 | K24: 0.7 | L24: Il reste le petit menu du bas, mais sélection d'artefacts est fonctionnel
B25: Peaufinage du lobby | C25: Fred | J25: 4 | K25: 1 | L25: Ne pas oublier de connecter FindMatch Command quand elle sera fonctionnel
B26: {=IFERROR( INDEX(Planification!B$2:B$100, SMALL( IF(Planification!C$2:C$100="Sprint 3", ROW(Planification!B$2:B$100)-ROW(Planification!B$2)+1), ROW(A22) ) ), "")}
B27: {=IFERROR( INDEX(Planification!B$2:B$100, SMALL( IF(Planification!C$2:C$100="Sprint 3", ROW(Planification!B$2:B$100)-ROW(Planification!B$2)+1), ROW(A23) ) ), "")}
B28: {=IFERROR( INDEX(Planification!B$2:B$100, SMALL( IF(Planification!C$2:C$100="Sprint 3", ROW(Planification!B$2:B$100)-ROW(Planification!B$2)+1), ROW(A24) ) ), "")}
B29: {=IFERROR( INDEX(Planification!B$2:B$100, SMALL( IF(Planification!C$2:C$100="Sprint 3", ROW(Planification!B$2:B$100)-ROW(Planification!B$2)+1), ROW(A25) ) ), "")}
B30: {=IFERROR( INDEX(Planification!B$2:B$100, SMALL( IF(Planification!C$2:C$100="Sprint 3", ROW(Planification!B$2:B$100)-ROW(Planification!B$2)+1), ROW(A26) ) ), "")}
B31: {=IFERROR( INDEX(Planification!B$2:B$100, SMALL( IF(Planification!C$2:C$100="Sprint 3", ROW(Planification!B$2:B$100)-ROW(Planification!B$2)+1), ROW(A27) ) ), "")}
B32: {=IFERROR( INDEX(Planification!B$2:B$100, SMALL( IF(Planification!C$2:C$100="Sprint 3", ROW(Planification!B$2:B$100)-ROW(Planification!B$2)+1), ROW(A28) ) ), "")}
B33: {=IFERROR( INDEX(Planification!B$2:B$100, SMALL( IF(Planification!C$2:C$100="Sprint 3", ROW(Planification!B$2:B$100)-ROW(Planification!B$2)+1), ROW(A29) ) ), "")}
B34: {=IFERROR( INDEX(Planification!B$2:B$100, SMALL( IF(Planification!C$2:C$100="Sprint 3", ROW(Planification!B$2:B$100)-ROW(Planification!B$2)+1), ROW(A30) ) ), "")}
B35: {=IFERROR( INDEX(Planification!B$2:B$100, SMALL( IF(Planification!C$2:C$100="Sprint 3", ROW(Planification!B$2:B$100)-ROW(Planification!B$2)+1), ROW(A31) ) ), "")}
B36: {=IFERROR( INDEX(Planification!B$2:B$100, SMALL( IF(Planification!C$2:C$100="Sprint 3", ROW(Planification!B$2:B$100)-ROW(Planification!B$2)+1), ROW(A32) ) ), "")}
B37: {=IFERROR( INDEX(Planification!B$2:B$100, SMALL( IF(Planification!C$2:C$100="Sprint 3", ROW(Planification!B$2:B$100)-ROW(Planification!B$2)+1), ROW(A33) ) ), "")}
... B41: {=IFERROR( INDEX(Planification!B$2:B$100, SMALL( IF(Planification!C$2:C$100="Sprint 3", ROW(Planification!B$2:B$100)-ROW(Planification!B$2)+1), ROW(A37) ) ), "")}

Sheet Sprint 4
B1: Sprint 4 | D1: Prioritaire | E1: Chocolat
D3: Semaine A | G3: Semaine B | J3: Semaine C | M3: Semaine D
B4: Tâche | C4: Responsable | D4: Temps (hrs) | E4: Avancement (%) | F4: Commentaires | G4: Temps | H4: Avancement | I4: Commentaires | J4: Temps | K4: Avancement | L4: Commentaires | M4: Temps | N4: Avancement | O4: Commentaires
B5: Stylisation de la page Partie (ajout d'image pour coeur, bouclier, prayer, roll) | C5: Fred | D5: 6 | E5: 0.5 | G5: 6 | H5: 1
B6: {=IFERROR( INDEX(Planification!B$2:B$100, SMALL( IF(Planification!C$2:C$100="Sprint 4", ROW(Planification!B$2:B$100)-ROW(Planification!B$2)+1), ROW(A2) ) ), "")} -> Ajout des parties jouées dans la BD | C6: Hugo | M6: 1 | N6: 1
B7: {=IFERROR( INDEX(Planification!B$2:B$100, SMALL( IF(Planification!C$2:C$100="Sprint 4", ROW(Planification!B$2:B$100)-ROW(Planification!B$2)+1), ROW(A3) ) ), "")} -> Création de la page Statistiques
B8: {=IFERROR( INDEX(Planification!B$2:B$100, SMALL( IF(Planification!C$2:C$100="Sprint 4", ROW(Planification!B$2:B$100)-ROW(Planification!B$2)+1), ROW(A4) ) ), "")} -> Creation des méthodes de DAO pour les dernières parties jouées | C8: Hugo | M8: 1 | N8: 1
B9: Ajouter des animations dans la AnimationQueue dans les resolve d'effets et de status | C9: Hugo | J9: 2 | K9: 0.3 | M9: 4 | N9: 1
B10: {=IFERROR( INDEX(Planification!B$2:B$100, SMALL( IF(Planification!C$2:C$100="Sprint 4", ROW(Planification!B$2:B$100)-ROW(Planification!B$2)+1), ROW(A6) ) ), "")} -> Ajouter plus de religion (6) et d'artefacts (24-30) | C10: Fred | J10: 2 | K10: 1 | L10: 4 religions et 20 artefacts
B11: {=IFERROR( INDEX(Planification!B$2:B$100, SMALL( IF(Planification!C$2:C$100="Sprint 4", ROW(Planification!B$2:B$100)-ROW(Planification!B$2)+1), ROW(A7) ) ), "")} -> Bonifier les gestures de partie (swipe pour roll, drag & drop dé) | C11: Fred | J11: 2 | K11: 1
B12: Animation des composantes lors du SOCKET EVENT ANIMATION | C12: Fred
B13: Ajout de sons et d'un audioPlayer | C13: Fred | M13: 5 | N13: 0.7
B14: Création du StatusPanel (infos et durée des statusEffect) | C14: Fred | M14: 3 | N14: 1
B15: Modifier les méta données Application (nom Icone, splashScreen)
B16: Gérer le timer pendant les animations | C16: Fred & Hugo | M16: 2 | N16: 1
B17: Ajouter menu artifact dans la partie (pour déclencher ArtifactCommand) | C17: Fred | J17: 5 | K17: 1
B18: Ajouter menu gods dans la partie (pour déclenecher GodCommand) | C18: Fred | J18: 5 | K18: 1
B19: Bonifier les action de L'IA | C19: Hugo | M19: 1 | N19: 0.75 | O19: on pourrais ajouter des reroll et changer le "build" (religion/artefact) du IA
B20: {=IFERROR( INDEX(Planification!B$2:B$100, SMALL( IF(Planification!C$2:C$100="Sprint 4", ROW(Planification!B$2:B$100)-ROW(Planification!B$2)+1), ROW(A10) ) ), "")} -> Ajouter un tutoriel pour les nouveaux usagers
B21: {=IFERROR( INDEX(Planification!B$2:B$100, SMALL( IF(Planification!C$2:C$100="Sprint 4", ROW(Planification!B$2:B$100)-ROW(Planification!B$2)+1), ROW(A11) ) ), "")} -> Ajouter un menu options (son, choix de langue)
B22: {=IFERROR( INDEX(Planification!B$2:B$100, SMALL( IF(Planification!C$2:C$100="Sprint 4", ROW(Planification!B$2:B$100)-ROW(Planification!B$2)+1), ROW(A13) ) ), "")} -> Ajout d'aide au Build (Artefacts recommandés)
B23: {=IFERROR( INDEX(Planification!B$2:B$100, SMALL( IF(Planification!C$2:C$100="Sprint 4", ROW(Planification!B$2:B$100)-ROW(Planification!B$2)+1), ROW(A19) ) ), "")}
B24: Ajouter un bouton règlements et les règlements | C24: Fred
B25: {=IFERROR( INDEX(Planification!B$2:B$100, SMALL( IF(Planification!C$2:C$100="Sprint 4", ROW(Planification!B$2:B$100)-ROW(Planification!B$2)+1), ROW(A21) ) ), "")}
B26: {=IFERROR( INDEX(Planification!B$2:B$100, SMALL( IF(Planification!C$2:C$100="Sprint 4", ROW(Planification!B$2:B$100)-ROW(Planification!B$2)+1), ROW(A22) ) ), "")}
B27: Ajouter une logique pour vérifier si le username est déjà utilisé lors d'un register | C27: Fred | J27: 1 | K27: 1
B28: Debug reconnection à une partie | C28: Fred & Hugo | G28: 2 | H28: 1
B29: Page Victoire dans partie (sur GameEnded) | C29: Fred
B30: implementation du système de ELO/Ranking | C30: Hugo | J30: 2 | K30: 1
B31: Debug des fonctionalitées et game loop | C31: Hugo | J31: 2 | K31: 1 | M31: 2 | N31: 1
B33: {=IFERROR( INDEX(Planification!B$2:B$100, SMALL( IF(Planification!C$2:C$100="Sprint 4", ROW(Planification!B$2:B$100)-ROW(Planification!B$2)+1), ROW(A29) ) ), "")}
B34: {=IFERROR( INDEX(Planification!B$2:B$100, SMALL( IF(Planification!C$2:C$100="Sprint 4", ROW(Planification!B$2:B$100)-ROW(Planification!B$2)+1), ROW(A30) ) ), "")}
B35: {=IFERROR( INDEX(Planification!B$2:B$100, SMALL( IF(Planification!C$2:C$100="Sprint 4", ROW(Planification!B$2:B$100)-ROW(Planification!B$2)+1), ROW(A31) ) ), "")}
B36: {=IFERROR( INDEX(Planification!B$2:B$100, SMALL( IF(Planification!C$2:C$100="Sprint 4", ROW(Planification!B$2:B$100)-ROW(Planification!B$2)+1), ROW(A32) ) ), "")}
B37: {=IFERROR( INDEX(Planification!B$2:B$100, SMALL( IF(Planification!C$2:C$100="Sprint 4", ROW(Planification!B$2:B$100)-ROW(Planification!B$2)+1), ROW(A33) ) ), "")}
B38: {=IFERROR( INDEX(Planification!B$2:B$100, SMALL( IF(Planification!C$2:C$100="Sprint 4", ROW(Planification!B$2:B$100)-ROW(Planification!B$2)+1), ROW(A34) ) ), "")}
B39: {=IFERROR( INDEX(Planification!B$2:B$100, SMALL( IF(Planification!C$2:C$100="Sprint 4", ROW(Planification!B$2:B$100)-ROW(Planification!B$2)+1), ROW(A35) ) ), "")}
B40: {=IFERROR( INDEX(Planification!B$2:B$100, SMALL( IF(Planification!C$2:C$100="Sprint 4", ROW(Planification!B$2:B$100)-ROW(Planification!B$2)+1), ROW(A36) ) ), "")}
B41: {=IFERROR( INDEX(Planification!B$2:B$100, SMALL( IF(Planification!C$2:C$100="Sprint 4", ROW(Planification!B$2:B$100)-ROW(Planification!B$2)+1), ROW(A37) ) ), "")}
B42: {=IFERROR( INDEX(Planification!B$2:B$100, SMALL( IF(Planification!C$2:C$100="Sprint 4", ROW(Planification!B$2:B$100)-ROW(Planification!B$2)+1), ROW(A38) ) ), "")}
...
